2023-08-18 08:21:47,779 INFO trace_id=0 span_id=0 resource.service.name=flask-app trace_sampled=False  * Running on all addresses (0.0.0.0)
   WARNING: This is a development server. Do not use it in a production deployment.
 * Running on http://127.0.0.1:80
 * Running on http://192.168.112.3:80 (Press CTRL+C to quit)
2023-08-18 08:21:47,792 INFO trace_id=0 span_id=0 resource.service.name=flask-app trace_sampled=False  * Restarting with stat
2023-08-18 08:21:48,693 WARNING trace_id=0 span_id=0 resource.service.name=flask-app trace_sampled=False  * Debugger is active!
2023-08-18 08:21:48,704 INFO trace_id=0 span_id=0 resource.service.name=flask-app trace_sampled=False  * Debugger PIN: 115-685-183
2023-08-18 08:21:51,952 INFO trace_id=af9fa976baea904c79b3fe7f98c623e7 span_id=4b31bd490167e531 resource.service.name=flask-app trace_sampled=True GET: 200 /
2023-08-18 08:21:51,965 INFO trace_id=0 span_id=0 resource.service.name=flask-app trace_sampled=False 127.0.0.1 - - [18/Aug/2023 08:21:51] "GET / HTTP/1.1" 200 -
2023-08-18 08:21:57,096 INFO trace_id=63730534f5de2d50a71dde5586033014 span_id=e871bcefc4848ddc resource.service.name=flask-app trace_sampled=True GET: 200 /
2023-08-18 08:21:57,097 INFO trace_id=0 span_id=0 resource.service.name=flask-app trace_sampled=False 127.0.0.1 - - [18/Aug/2023 08:21:57] "GET / HTTP/1.1" 200 -
Exception while exporting Span batch.
Traceback (most recent call last):
  File "/usr/local/lib/python3.10/site-packages/opentelemetry/sdk/trace/export/__init__.py", line 368, in _export_batch
    self.span_exporter.export(self.spans_list[:idx])  # type: ignore
  File "/usr/local/lib/python3.10/site-packages/opentelemetry/exporter/jaeger/thrift/__init__.py", line 225, in export
    self._agent_client.emit(batch)
  File "/usr/local/lib/python3.10/site-packages/opentelemetry/exporter/jaeger/thrift/send.py", line 95, in emit
    udp_socket.sendto(buff, self.address)
socket.gaierror: [Errno -3] Try again
2023-08-18 08:21:58,670 ERROR trace_id=0 span_id=0 resource.service.name=flask-app trace_sampled=False Exception while exporting Span batch.
Traceback (most recent call last):
  File "/usr/local/lib/python3.10/site-packages/opentelemetry/sdk/trace/export/__init__.py", line 368, in _export_batch
    self.span_exporter.export(self.spans_list[:idx])  # type: ignore
  File "/usr/local/lib/python3.10/site-packages/opentelemetry/exporter/jaeger/thrift/__init__.py", line 225, in export
    self._agent_client.emit(batch)
  File "/usr/local/lib/python3.10/site-packages/opentelemetry/exporter/jaeger/thrift/send.py", line 95, in emit
    udp_socket.sendto(buff, self.address)
socket.gaierror: [Errno -3] Try again
2023-08-18 08:22:02,227 INFO trace_id=403d42dc4f9a0b746eb1acd8d97e39a4 span_id=b34ed571c42710e8 resource.service.name=flask-app trace_sampled=True GET: 200 /
2023-08-18 08:22:02,229 INFO trace_id=0 span_id=0 resource.service.name=flask-app trace_sampled=False 127.0.0.1 - - [18/Aug/2023 08:22:02] "GET / HTTP/1.1" 200 -
Exception while exporting Span batch.
Traceback (most recent call last):
  File "/usr/local/lib/python3.10/site-packages/opentelemetry/sdk/trace/export/__init__.py", line 368, in _export_batch
    self.span_exporter.export(self.spans_list[:idx])  # type: ignore
  File "/usr/local/lib/python3.10/site-packages/opentelemetry/exporter/jaeger/thrift/__init__.py", line 225, in export
    self._agent_client.emit(batch)
  File "/usr/local/lib/python3.10/site-packages/opentelemetry/exporter/jaeger/thrift/send.py", line 95, in emit
    udp_socket.sendto(buff, self.address)
socket.gaierror: [Errno -3] Try again
2023-08-18 08:22:03,679 ERROR trace_id=0 span_id=0 resource.service.name=flask-app trace_sampled=False Exception while exporting Span batch.
Traceback (most recent call last):
  File "/usr/local/lib/python3.10/site-packages/opentelemetry/sdk/trace/export/__init__.py", line 368, in _export_batch
    self.span_exporter.export(self.spans_list[:idx])  # type: ignore
  File "/usr/local/lib/python3.10/site-packages/opentelemetry/exporter/jaeger/thrift/__init__.py", line 225, in export
    self._agent_client.emit(batch)
  File "/usr/local/lib/python3.10/site-packages/opentelemetry/exporter/jaeger/thrift/send.py", line 95, in emit
    udp_socket.sendto(buff, self.address)
socket.gaierror: [Errno -3] Try again
2023-08-18 08:22:07,363 INFO trace_id=6fb6b6c4eed3d0023b662f7f9d9b3d7f span_id=62709e8ef53acdd2 resource.service.name=flask-app trace_sampled=True GET: 200 /
2023-08-18 08:22:07,365 INFO trace_id=0 span_id=0 resource.service.name=flask-app trace_sampled=False 127.0.0.1 - - [18/Aug/2023 08:22:07] "GET / HTTP/1.1" 200 -
Exception while exporting Span batch.
Traceback (most recent call last):
  File "/usr/local/lib/python3.10/site-packages/opentelemetry/sdk/trace/export/__init__.py", line 368, in _export_batch
    self.span_exporter.export(self.spans_list[:idx])  # type: ignore
  File "/usr/local/lib/python3.10/site-packages/opentelemetry/exporter/jaeger/thrift/__init__.py", line 225, in export
    self._agent_client.emit(batch)
  File "/usr/local/lib/python3.10/site-packages/opentelemetry/exporter/jaeger/thrift/send.py", line 95, in emit
    udp_socket.sendto(buff, self.address)
socket.gaierror: [Errno -3] Try again
2023-08-18 08:22:08,686 ERROR trace_id=0 span_id=0 resource.service.name=flask-app trace_sampled=False Exception while exporting Span batch.
Traceback (most recent call last):
  File "/usr/local/lib/python3.10/site-packages/opentelemetry/sdk/trace/export/__init__.py", line 368, in _export_batch
    self.span_exporter.export(self.spans_list[:idx])  # type: ignore
  File "/usr/local/lib/python3.10/site-packages/opentelemetry/exporter/jaeger/thrift/__init__.py", line 225, in export
    self._agent_client.emit(batch)
  File "/usr/local/lib/python3.10/site-packages/opentelemetry/exporter/jaeger/thrift/send.py", line 95, in emit
    udp_socket.sendto(buff, self.address)
socket.gaierror: [Errno -3] Try again
2023-08-18 08:22:12,498 INFO trace_id=38e98616c881a876e723fba886abc8ec span_id=d5c40f9191ff5008 resource.service.name=flask-app trace_sampled=True GET: 200 /
2023-08-18 08:22:12,500 INFO trace_id=0 span_id=0 resource.service.name=flask-app trace_sampled=False 127.0.0.1 - - [18/Aug/2023 08:22:12] "GET / HTTP/1.1" 200 -
Exception while exporting Span batch.
Traceback (most recent call last):
  File "/usr/local/lib/python3.10/site-packages/opentelemetry/sdk/trace/export/__init__.py", line 368, in _export_batch
    self.span_exporter.export(self.spans_list[:idx])  # type: ignore
  File "/usr/local/lib/python3.10/site-packages/opentelemetry/exporter/jaeger/thrift/__init__.py", line 225, in export
    self._agent_client.emit(batch)
  File "/usr/local/lib/python3.10/site-packages/opentelemetry/exporter/jaeger/thrift/send.py", line 95, in emit
    udp_socket.sendto(buff, self.address)
socket.gaierror: [Errno -3] Try again
2023-08-18 08:22:13,695 ERROR trace_id=0 span_id=0 resource.service.name=flask-app trace_sampled=False Exception while exporting Span batch.
Traceback (most recent call last):
  File "/usr/local/lib/python3.10/site-packages/opentelemetry/sdk/trace/export/__init__.py", line 368, in _export_batch
    self.span_exporter.export(self.spans_list[:idx])  # type: ignore
  File "/usr/local/lib/python3.10/site-packages/opentelemetry/exporter/jaeger/thrift/__init__.py", line 225, in export
    self._agent_client.emit(batch)
  File "/usr/local/lib/python3.10/site-packages/opentelemetry/exporter/jaeger/thrift/send.py", line 95, in emit
    udp_socket.sendto(buff, self.address)
socket.gaierror: [Errno -3] Try again
2023-08-18 08:22:17,644 INFO trace_id=269da35b0f0183fb727caddf50baeaa4 span_id=f10dc0c41b948657 resource.service.name=flask-app trace_sampled=True GET: 200 /
2023-08-18 08:22:17,646 INFO trace_id=0 span_id=0 resource.service.name=flask-app trace_sampled=False 127.0.0.1 - - [18/Aug/2023 08:22:17] "GET / HTTP/1.1" 200 -
Exception while exporting Span batch.
Traceback (most recent call last):
  File "/usr/local/lib/python3.10/site-packages/opentelemetry/sdk/trace/export/__init__.py", line 368, in _export_batch
    self.span_exporter.export(self.spans_list[:idx])  # type: ignore
  File "/usr/local/lib/python3.10/site-packages/opentelemetry/exporter/jaeger/thrift/__init__.py", line 225, in export
    self._agent_client.emit(batch)
  File "/usr/local/lib/python3.10/site-packages/opentelemetry/exporter/jaeger/thrift/send.py", line 95, in emit
    udp_socket.sendto(buff, self.address)
socket.gaierror: [Errno -3] Try again
2023-08-18 08:22:18,702 ERROR trace_id=0 span_id=0 resource.service.name=flask-app trace_sampled=False Exception while exporting Span batch.
Traceback (most recent call last):
  File "/usr/local/lib/python3.10/site-packages/opentelemetry/sdk/trace/export/__init__.py", line 368, in _export_batch
    self.span_exporter.export(self.spans_list[:idx])  # type: ignore
  File "/usr/local/lib/python3.10/site-packages/opentelemetry/exporter/jaeger/thrift/__init__.py", line 225, in export
    self._agent_client.emit(batch)
  File "/usr/local/lib/python3.10/site-packages/opentelemetry/exporter/jaeger/thrift/send.py", line 95, in emit
    udp_socket.sendto(buff, self.address)
socket.gaierror: [Errno -3] Try again
2023-08-18 08:22:22,779 INFO trace_id=42ec2b1556b597827abe2cf410968071 span_id=73c0758dc4659261 resource.service.name=flask-app trace_sampled=True GET: 200 /
2023-08-18 08:22:22,780 INFO trace_id=0 span_id=0 resource.service.name=flask-app trace_sampled=False 127.0.0.1 - - [18/Aug/2023 08:22:22] "GET / HTTP/1.1" 200 -
Exception while exporting Span batch.
Traceback (most recent call last):
  File "/usr/local/lib/python3.10/site-packages/opentelemetry/sdk/trace/export/__init__.py", line 368, in _export_batch
    self.span_exporter.export(self.spans_list[:idx])  # type: ignore
  File "/usr/local/lib/python3.10/site-packages/opentelemetry/exporter/jaeger/thrift/__init__.py", line 225, in export
    self._agent_client.emit(batch)
  File "/usr/local/lib/python3.10/site-packages/opentelemetry/exporter/jaeger/thrift/send.py", line 95, in emit
    udp_socket.sendto(buff, self.address)
socket.gaierror: [Errno -3] Try again
2023-08-18 08:22:23,707 ERROR trace_id=0 span_id=0 resource.service.name=flask-app trace_sampled=False Exception while exporting Span batch.
Traceback (most recent call last):
  File "/usr/local/lib/python3.10/site-packages/opentelemetry/sdk/trace/export/__init__.py", line 368, in _export_batch
    self.span_exporter.export(self.spans_list[:idx])  # type: ignore
  File "/usr/local/lib/python3.10/site-packages/opentelemetry/exporter/jaeger/thrift/__init__.py", line 225, in export
    self._agent_client.emit(batch)
  File "/usr/local/lib/python3.10/site-packages/opentelemetry/exporter/jaeger/thrift/send.py", line 95, in emit
    udp_socket.sendto(buff, self.address)
socket.gaierror: [Errno -3] Try again
2023-08-18 08:22:27,906 INFO trace_id=4ab7ef945cf4056620b1afa4c5cb38a8 span_id=f6183cb4ea062f43 resource.service.name=flask-app trace_sampled=True GET: 200 /
2023-08-18 08:22:27,907 INFO trace_id=0 span_id=0 resource.service.name=flask-app trace_sampled=False 127.0.0.1 - - [18/Aug/2023 08:22:27] "GET / HTTP/1.1" 200 -
Exception while exporting Span batch.
Traceback (most recent call last):
  File "/usr/local/lib/python3.10/site-packages/opentelemetry/sdk/trace/export/__init__.py", line 368, in _export_batch
    self.span_exporter.export(self.spans_list[:idx])  # type: ignore
  File "/usr/local/lib/python3.10/site-packages/opentelemetry/exporter/jaeger/thrift/__init__.py", line 225, in export
    self._agent_client.emit(batch)
  File "/usr/local/lib/python3.10/site-packages/opentelemetry/exporter/jaeger/thrift/send.py", line 95, in emit
    udp_socket.sendto(buff, self.address)
socket.gaierror: [Errno -3] Try again
2023-08-18 08:22:28,714 ERROR trace_id=0 span_id=0 resource.service.name=flask-app trace_sampled=False Exception while exporting Span batch.
Traceback (most recent call last):
  File "/usr/local/lib/python3.10/site-packages/opentelemetry/sdk/trace/export/__init__.py", line 368, in _export_batch
    self.span_exporter.export(self.spans_list[:idx])  # type: ignore
  File "/usr/local/lib/python3.10/site-packages/opentelemetry/exporter/jaeger/thrift/__init__.py", line 225, in export
    self._agent_client.emit(batch)
  File "/usr/local/lib/python3.10/site-packages/opentelemetry/exporter/jaeger/thrift/send.py", line 95, in emit
    udp_socket.sendto(buff, self.address)
socket.gaierror: [Errno -3] Try again
2023-08-18 08:22:33,040 INFO trace_id=2756ac0934e3f2a5e0d3ffeba516de77 span_id=7c2bef52cdd8ac51 resource.service.name=flask-app trace_sampled=True GET: 200 /
2023-08-18 08:22:33,042 INFO trace_id=0 span_id=0 resource.service.name=flask-app trace_sampled=False 127.0.0.1 - - [18/Aug/2023 08:22:33] "GET / HTTP/1.1" 200 -
Exception while exporting Span batch.
Traceback (most recent call last):
  File "/usr/local/lib/python3.10/site-packages/opentelemetry/sdk/trace/export/__init__.py", line 368, in _export_batch
    self.span_exporter.export(self.spans_list[:idx])  # type: ignore
  File "/usr/local/lib/python3.10/site-packages/opentelemetry/exporter/jaeger/thrift/__init__.py", line 225, in export
    self._agent_client.emit(batch)
  File "/usr/local/lib/python3.10/site-packages/opentelemetry/exporter/jaeger/thrift/send.py", line 95, in emit
    udp_socket.sendto(buff, self.address)
socket.gaierror: [Errno -3] Try again
2023-08-18 08:22:33,722 ERROR trace_id=0 span_id=0 resource.service.name=flask-app trace_sampled=False Exception while exporting Span batch.
Traceback (most recent call last):
  File "/usr/local/lib/python3.10/site-packages/opentelemetry/sdk/trace/export/__init__.py", line 368, in _export_batch
    self.span_exporter.export(self.spans_list[:idx])  # type: ignore
  File "/usr/local/lib/python3.10/site-packages/opentelemetry/exporter/jaeger/thrift/__init__.py", line 225, in export
    self._agent_client.emit(batch)
  File "/usr/local/lib/python3.10/site-packages/opentelemetry/exporter/jaeger/thrift/send.py", line 95, in emit
    udp_socket.sendto(buff, self.address)
socket.gaierror: [Errno -3] Try again
2023-08-18 08:22:38,180 INFO trace_id=206e32374ea45fdf82cecf321afc47bd span_id=5f71aac501b0fdb3 resource.service.name=flask-app trace_sampled=True GET: 200 /
2023-08-18 08:22:38,181 INFO trace_id=0 span_id=0 resource.service.name=flask-app trace_sampled=False 127.0.0.1 - - [18/Aug/2023 08:22:38] "GET / HTTP/1.1" 200 -
Exception while exporting Span batch.
Traceback (most recent call last):
  File "/usr/local/lib/python3.10/site-packages/opentelemetry/sdk/trace/export/__init__.py", line 368, in _export_batch
    self.span_exporter.export(self.spans_list[:idx])  # type: ignore
  File "/usr/local/lib/python3.10/site-packages/opentelemetry/exporter/jaeger/thrift/__init__.py", line 225, in export
    self._agent_client.emit(batch)
  File "/usr/local/lib/python3.10/site-packages/opentelemetry/exporter/jaeger/thrift/send.py", line 95, in emit
    udp_socket.sendto(buff, self.address)
socket.gaierror: [Errno -3] Try again
2023-08-18 08:22:38,731 ERROR trace_id=0 span_id=0 resource.service.name=flask-app trace_sampled=False Exception while exporting Span batch.
Traceback (most recent call last):
  File "/usr/local/lib/python3.10/site-packages/opentelemetry/sdk/trace/export/__init__.py", line 368, in _export_batch
    self.span_exporter.export(self.spans_list[:idx])  # type: ignore
  File "/usr/local/lib/python3.10/site-packages/opentelemetry/exporter/jaeger/thrift/__init__.py", line 225, in export
    self._agent_client.emit(batch)
  File "/usr/local/lib/python3.10/site-packages/opentelemetry/exporter/jaeger/thrift/send.py", line 95, in emit
    udp_socket.sendto(buff, self.address)
socket.gaierror: [Errno -3] Try again
2023-08-18 08:22:43,318 INFO trace_id=56d4c53da8fee0a74e7fb727127391cc span_id=3b6c2b6a74a4fd48 resource.service.name=flask-app trace_sampled=True GET: 200 /
2023-08-18 08:22:43,320 INFO trace_id=0 span_id=0 resource.service.name=flask-app trace_sampled=False 127.0.0.1 - - [18/Aug/2023 08:22:43] "GET / HTTP/1.1" 200 -
Exception while exporting Span batch.
Traceback (most recent call last):
  File "/usr/local/lib/python3.10/site-packages/opentelemetry/sdk/trace/export/__init__.py", line 368, in _export_batch
    self.span_exporter.export(self.spans_list[:idx])  # type: ignore
  File "/usr/local/lib/python3.10/site-packages/opentelemetry/exporter/jaeger/thrift/__init__.py", line 225, in export
    self._agent_client.emit(batch)
  File "/usr/local/lib/python3.10/site-packages/opentelemetry/exporter/jaeger/thrift/send.py", line 95, in emit
    udp_socket.sendto(buff, self.address)
socket.gaierror: [Errno -3] Try again
2023-08-18 08:22:43,738 ERROR trace_id=0 span_id=0 resource.service.name=flask-app trace_sampled=False Exception while exporting Span batch.
Traceback (most recent call last):
  File "/usr/local/lib/python3.10/site-packages/opentelemetry/sdk/trace/export/__init__.py", line 368, in _export_batch
    self.span_exporter.export(self.spans_list[:idx])  # type: ignore
  File "/usr/local/lib/python3.10/site-packages/opentelemetry/exporter/jaeger/thrift/__init__.py", line 225, in export
    self._agent_client.emit(batch)
  File "/usr/local/lib/python3.10/site-packages/opentelemetry/exporter/jaeger/thrift/send.py", line 95, in emit
    udp_socket.sendto(buff, self.address)
socket.gaierror: [Errno -3] Try again
2023-08-18 08:22:48,467 INFO trace_id=cf9d44c6161702afb1a478367cbd5871 span_id=f6dc600f041267e4 resource.service.name=flask-app trace_sampled=True GET: 200 /
2023-08-18 08:22:48,468 INFO trace_id=0 span_id=0 resource.service.name=flask-app trace_sampled=False 127.0.0.1 - - [18/Aug/2023 08:22:48] "GET / HTTP/1.1" 200 -
Exception while exporting Span batch.
Traceback (most recent call last):
  File "/usr/local/lib/python3.10/site-packages/opentelemetry/sdk/trace/export/__init__.py", line 368, in _export_batch
    self.span_exporter.export(self.spans_list[:idx])  # type: ignore
  File "/usr/local/lib/python3.10/site-packages/opentelemetry/exporter/jaeger/thrift/__init__.py", line 225, in export
    self._agent_client.emit(batch)
  File "/usr/local/lib/python3.10/site-packages/opentelemetry/exporter/jaeger/thrift/send.py", line 95, in emit
    udp_socket.sendto(buff, self.address)
socket.gaierror: [Errno -3] Try again
2023-08-18 08:22:48,746 ERROR trace_id=0 span_id=0 resource.service.name=flask-app trace_sampled=False Exception while exporting Span batch.
Traceback (most recent call last):
  File "/usr/local/lib/python3.10/site-packages/opentelemetry/sdk/trace/export/__init__.py", line 368, in _export_batch
    self.span_exporter.export(self.spans_list[:idx])  # type: ignore
  File "/usr/local/lib/python3.10/site-packages/opentelemetry/exporter/jaeger/thrift/__init__.py", line 225, in export
    self._agent_client.emit(batch)
  File "/usr/local/lib/python3.10/site-packages/opentelemetry/exporter/jaeger/thrift/send.py", line 95, in emit
    udp_socket.sendto(buff, self.address)
socket.gaierror: [Errno -3] Try again
2023-08-18 08:22:53,617 INFO trace_id=1660c8fa190bdd385bf47453e6be4def span_id=5bf0861b06b3be7a resource.service.name=flask-app trace_sampled=True GET: 200 /
2023-08-18 08:22:53,618 INFO trace_id=0 span_id=0 resource.service.name=flask-app trace_sampled=False 127.0.0.1 - - [18/Aug/2023 08:22:53] "GET / HTTP/1.1" 200 -
Exception while exporting Span batch.
Traceback (most recent call last):
  File "/usr/local/lib/python3.10/site-packages/opentelemetry/sdk/trace/export/__init__.py", line 368, in _export_batch
    self.span_exporter.export(self.spans_list[:idx])  # type: ignore
  File "/usr/local/lib/python3.10/site-packages/opentelemetry/exporter/jaeger/thrift/__init__.py", line 225, in export
    self._agent_client.emit(batch)
  File "/usr/local/lib/python3.10/site-packages/opentelemetry/exporter/jaeger/thrift/send.py", line 95, in emit
    udp_socket.sendto(buff, self.address)
socket.gaierror: [Errno -3] Try again
2023-08-18 08:22:53,753 ERROR trace_id=0 span_id=0 resource.service.name=flask-app trace_sampled=False Exception while exporting Span batch.
Traceback (most recent call last):
  File "/usr/local/lib/python3.10/site-packages/opentelemetry/sdk/trace/export/__init__.py", line 368, in _export_batch
    self.span_exporter.export(self.spans_list[:idx])  # type: ignore
  File "/usr/local/lib/python3.10/site-packages/opentelemetry/exporter/jaeger/thrift/__init__.py", line 225, in export
    self._agent_client.emit(batch)
  File "/usr/local/lib/python3.10/site-packages/opentelemetry/exporter/jaeger/thrift/send.py", line 95, in emit
    udp_socket.sendto(buff, self.address)
socket.gaierror: [Errno -3] Try again
2023-08-18 08:22:58,750 INFO trace_id=e53932d8a7f88d2c7ff5a08cfae0d207 span_id=20f054c0a219224c resource.service.name=flask-app trace_sampled=True GET: 200 /
2023-08-18 08:22:58,751 INFO trace_id=0 span_id=0 resource.service.name=flask-app trace_sampled=False 127.0.0.1 - - [18/Aug/2023 08:22:58] "GET / HTTP/1.1" 200 -
Exception while exporting Span batch.
Traceback (most recent call last):
  File "/usr/local/lib/python3.10/site-packages/opentelemetry/sdk/trace/export/__init__.py", line 368, in _export_batch
    self.span_exporter.export(self.spans_list[:idx])  # type: ignore
  File "/usr/local/lib/python3.10/site-packages/opentelemetry/exporter/jaeger/thrift/__init__.py", line 225, in export
    self._agent_client.emit(batch)
  File "/usr/local/lib/python3.10/site-packages/opentelemetry/exporter/jaeger/thrift/send.py", line 95, in emit
    udp_socket.sendto(buff, self.address)
socket.gaierror: [Errno -3] Try again
2023-08-18 08:22:58,762 ERROR trace_id=0 span_id=0 resource.service.name=flask-app trace_sampled=False Exception while exporting Span batch.
Traceback (most recent call last):
  File "/usr/local/lib/python3.10/site-packages/opentelemetry/sdk/trace/export/__init__.py", line 368, in _export_batch
    self.span_exporter.export(self.spans_list[:idx])  # type: ignore
  File "/usr/local/lib/python3.10/site-packages/opentelemetry/exporter/jaeger/thrift/__init__.py", line 225, in export
    self._agent_client.emit(batch)
  File "/usr/local/lib/python3.10/site-packages/opentelemetry/exporter/jaeger/thrift/send.py", line 95, in emit
    udp_socket.sendto(buff, self.address)
socket.gaierror: [Errno -3] Try again
Exception while exporting Span batch.
Traceback (most recent call last):
  File "/usr/local/lib/python3.10/site-packages/opentelemetry/sdk/trace/export/__init__.py", line 368, in _export_batch
    self.span_exporter.export(self.spans_list[:idx])  # type: ignore
  File "/usr/local/lib/python3.10/site-packages/opentelemetry/exporter/jaeger/thrift/__init__.py", line 225, in export
    self._agent_client.emit(batch)
  File "/usr/local/lib/python3.10/site-packages/opentelemetry/exporter/jaeger/thrift/send.py", line 95, in emit
    udp_socket.sendto(buff, self.address)
socket.gaierror: [Errno -3] Try again
2023-08-18 08:23:03,768 ERROR trace_id=0 span_id=0 resource.service.name=flask-app trace_sampled=False Exception while exporting Span batch.
Traceback (most recent call last):
  File "/usr/local/lib/python3.10/site-packages/opentelemetry/sdk/trace/export/__init__.py", line 368, in _export_batch
    self.span_exporter.export(self.spans_list[:idx])  # type: ignore
  File "/usr/local/lib/python3.10/site-packages/opentelemetry/exporter/jaeger/thrift/__init__.py", line 225, in export
    self._agent_client.emit(batch)
  File "/usr/local/lib/python3.10/site-packages/opentelemetry/exporter/jaeger/thrift/send.py", line 95, in emit
    udp_socket.sendto(buff, self.address)
socket.gaierror: [Errno -3] Try again
2023-08-18 08:23:03,843 INFO trace_id=e6f0d3dce647b107ff0eac90b1d650eb span_id=1334686c488f35d7 resource.service.name=flask-app trace_sampled=True GET: 200 /
2023-08-18 08:23:03,845 INFO trace_id=0 span_id=0 resource.service.name=flask-app trace_sampled=False 127.0.0.1 - - [18/Aug/2023 08:23:03] "GET / HTTP/1.1" 200 -
2023-08-18 08:23:08,990 INFO trace_id=8e900aa22612313bfd5116e1d99c59cc span_id=96d41d925c9fbbc7 resource.service.name=flask-app trace_sampled=True GET: 200 /
2023-08-18 08:23:08,992 INFO trace_id=0 span_id=0 resource.service.name=flask-app trace_sampled=False 127.0.0.1 - - [18/Aug/2023 08:23:08] "GET / HTTP/1.1" 200 -
2023-08-18 08:23:39,875 INFO trace_id=0 span_id=0 resource.service.name=flask-app trace_sampled=False  * Running on all addresses (0.0.0.0)
   WARNING: This is a development server. Do not use it in a production deployment.
 * Running on http://127.0.0.1:80
 * Running on http://192.168.160.3:80 (Press CTRL+C to quit)
2023-08-18 08:23:39,887 INFO trace_id=0 span_id=0 resource.service.name=flask-app trace_sampled=False  * Restarting with stat
2023-08-18 08:23:40,755 WARNING trace_id=0 span_id=0 resource.service.name=flask-app trace_sampled=False  * Debugger is active!
2023-08-18 08:23:40,765 INFO trace_id=0 span_id=0 resource.service.name=flask-app trace_sampled=False  * Debugger PIN: 310-423-326
2023-08-18 08:23:44,005 INFO trace_id=18ee48195489b13979664c2109125d73 span_id=b2566d761e6e342d resource.service.name=flask-app trace_sampled=True GET: 200 /
2023-08-18 08:23:44,019 INFO trace_id=0 span_id=0 resource.service.name=flask-app trace_sampled=False 127.0.0.1 - - [18/Aug/2023 08:23:44] "GET / HTTP/1.1" 200 -
2023-08-18 08:23:49,155 INFO trace_id=b1b6159b45d839c0c02feebc34fd9454 span_id=73877a665fb21e05 resource.service.name=flask-app trace_sampled=True GET: 200 /
2023-08-18 08:23:49,157 INFO trace_id=0 span_id=0 resource.service.name=flask-app trace_sampled=False 127.0.0.1 - - [18/Aug/2023 08:23:49] "GET / HTTP/1.1" 200 -
2023-08-18 08:23:54,295 INFO trace_id=4b55a3d8f84a3de7ed7de0da18695716 span_id=c4aa9b2ddccf6075 resource.service.name=flask-app trace_sampled=True GET: 200 /
2023-08-18 08:23:54,296 INFO trace_id=0 span_id=0 resource.service.name=flask-app trace_sampled=False 127.0.0.1 - - [18/Aug/2023 08:23:54] "GET / HTTP/1.1" 200 -
2023-08-18 08:23:59,420 INFO trace_id=92a6d38d6efb69ba165998cac06eaf30 span_id=d01ac49663b284d5 resource.service.name=flask-app trace_sampled=True GET: 200 /
2023-08-18 08:23:59,422 INFO trace_id=0 span_id=0 resource.service.name=flask-app trace_sampled=False 127.0.0.1 - - [18/Aug/2023 08:23:59] "GET / HTTP/1.1" 200 -
2023-08-18 08:24:04,553 INFO trace_id=7ee78539a8ebbee02c5e9a7c9a2764ba span_id=ff6b475791979425 resource.service.name=flask-app trace_sampled=True GET: 200 /
2023-08-18 08:24:04,555 INFO trace_id=0 span_id=0 resource.service.name=flask-app trace_sampled=False 127.0.0.1 - - [18/Aug/2023 08:24:04] "GET / HTTP/1.1" 200 -
2023-08-18 08:24:09,713 INFO trace_id=825ec02ca3ce73f6eee2d15d60a1cdac span_id=e99d2162ab324d82 resource.service.name=flask-app trace_sampled=True GET: 200 /
2023-08-18 08:24:09,716 INFO trace_id=0 span_id=0 resource.service.name=flask-app trace_sampled=False 127.0.0.1 - - [18/Aug/2023 08:24:09] "GET / HTTP/1.1" 200 -
2023-08-18 08:24:14,847 INFO trace_id=f8202e4c196f535493a10f8bb87615ae span_id=f93fa93acea3aeeb resource.service.name=flask-app trace_sampled=True GET: 200 /
2023-08-18 08:24:14,849 INFO trace_id=0 span_id=0 resource.service.name=flask-app trace_sampled=False 127.0.0.1 - - [18/Aug/2023 08:24:14] "GET / HTTP/1.1" 200 -
2023-08-18 08:24:19,977 INFO trace_id=50f89ae3d86a6cd880f3aef44ca3ef29 span_id=44b5d3060ac9b09d resource.service.name=flask-app trace_sampled=True GET: 200 /
2023-08-18 08:24:19,979 INFO trace_id=0 span_id=0 resource.service.name=flask-app trace_sampled=False 127.0.0.1 - - [18/Aug/2023 08:24:19] "GET / HTTP/1.1" 200 -
2023-08-18 08:24:25,117 INFO trace_id=4215d145dfd731f5fba1615cd0d412cd span_id=e36667259231caae resource.service.name=flask-app trace_sampled=True GET: 200 /
2023-08-18 08:24:25,118 INFO trace_id=0 span_id=0 resource.service.name=flask-app trace_sampled=False 127.0.0.1 - - [18/Aug/2023 08:24:25] "GET / HTTP/1.1" 200 -
2023-08-18 08:24:30,256 INFO trace_id=ff89ec1ab6488620e204d588dd30c4b5 span_id=86909ce10dbc2bb0 resource.service.name=flask-app trace_sampled=True GET: 200 /
2023-08-18 08:24:30,258 INFO trace_id=0 span_id=0 resource.service.name=flask-app trace_sampled=False 127.0.0.1 - - [18/Aug/2023 08:24:30] "GET / HTTP/1.1" 200 -
Exception while exporting Span batch.
Traceback (most recent call last):
  File "/usr/local/lib/python3.10/site-packages/opentelemetry/sdk/trace/export/__init__.py", line 368, in _export_batch
    self.span_exporter.export(self.spans_list[:idx])  # type: ignore
  File "/usr/local/lib/python3.10/site-packages/opentelemetry/exporter/jaeger/thrift/__init__.py", line 225, in export
    self._agent_client.emit(batch)
  File "/usr/local/lib/python3.10/site-packages/opentelemetry/exporter/jaeger/thrift/send.py", line 95, in emit
    udp_socket.sendto(buff, self.address)
socket.gaierror: [Errno -3] Try again
2023-08-18 08:24:30,737 ERROR trace_id=0 span_id=0 resource.service.name=flask-app trace_sampled=False Exception while exporting Span batch.
Traceback (most recent call last):
  File "/usr/local/lib/python3.10/site-packages/opentelemetry/sdk/trace/export/__init__.py", line 368, in _export_batch
    self.span_exporter.export(self.spans_list[:idx])  # type: ignore
  File "/usr/local/lib/python3.10/site-packages/opentelemetry/exporter/jaeger/thrift/__init__.py", line 225, in export
    self._agent_client.emit(batch)
  File "/usr/local/lib/python3.10/site-packages/opentelemetry/exporter/jaeger/thrift/send.py", line 95, in emit
    udp_socket.sendto(buff, self.address)
socket.gaierror: [Errno -3] Try again
